<?xml version="1.0"?>
<robot name="sweeper_robot_omni4_base">
  <material name="chassis_dark">
    <color rgba="0.10 0.13 0.13 1.0" />
  </material>
  <material name="chassis_top">
    <color rgba="0.23 0.26 0.27 1.0" />
  </material>
  <material name="mount_dark">
    <color rgba="0.02 0.025 0.028 1.0" />
  </material>
  <material name="axle_silver">
    <color rgba="0.72 0.72 0.68 1.0" />
  </material>
  <material name="wheel_silver">
    <color rgba="0.92 0.91 0.86 1.0" />
  </material>
  <material name="roller_light">
    <color rgba="0.86 0.86 0.82 1.0" />
  </material>
  <material name="lidar_blue">
    <color rgba="0.0 0.42 0.68 1.0" />
  </material>
  <material name="odometry_orange">
    <color rgba="0.86 0.38 0.0 1.0" />
  </material>
  <material name="sensor_dark">
    <color rgba="0.02 0.025 0.03 1.0" />
  </material>
  <material name="interface_green">
    <color rgba="0.02 0.55 0.22 1.0" />
  </material>
  <material name="interface_gold">
    <color rgba="0.95 0.70 0.20 1.0" />
  </material>
  <link name="base_footprint" />
  <joint name="base_footprint_joint" type="fixed">
    <parent link="base_footprint" />
    <child link="base_link" />
    <origin xyz="0 0 0" rpy="0 0 0" />
  </joint>
  <link name="base_link">
    <inertial>
      <origin xyz="0 0 0.125" rpy="0 0 0" />
      <mass value="4.00000" />
      <inertia ixx="0.06370000" ixy="0" ixz="0" iyy="0.06370000" iyz="0" izz="0.12500000" />
    </inertial>
    <visual name="single_round_0p5m_chassis">
      <origin xyz="0 0 0.1250" rpy="0 0 0" />
      <geometry>
        <cylinder radius="0.2500" length="0.0600" />
      </geometry>
      <material name="chassis_dark" />
    </visual>
    <visual name="slightly_raised_top_plate">
      <origin xyz="0 0 0.1570" rpy="0 0 0" />
      <geometry>
        <cylinder radius="0.2350" length="0.0060" />
      </geometry>
      <material name="chassis_top" />
    </visual>
    <visual name="lower_diagonal_support_beam_a">
      <origin xyz="0 0 0.0790" rpy="0 0 0.7854" />
      <geometry>
        <box size="0.335 0.032 0.026" />
      </geometry>
      <material name="mount_dark" />
    </visual>
    <visual name="lower_diagonal_support_beam_b">
      <origin xyz="0 0 0.0790" rpy="0 0 -0.7854" />
      <geometry>
        <box size="0.335 0.032 0.026" />
      </geometry>
      <material name="mount_dark" />
    </visual>
    <visual name="lower_center_axle_hub">
      <origin xyz="0 0 0.0790" rpy="0 0 0" />
      <geometry>
        <cylinder radius="0.0480" length="0.0300" />
      </geometry>
      <material name="mount_dark" />
    </visual>
    <visual name="front_left_inner_axle_bracket">
      <origin xyz="0.0955 0.0955 0.0810" rpy="0 0 -0.7854" />
      <geometry>
        <box size="0.052 0.034 0.060" />
      </geometry>
      <material name="mount_dark" />
    </visual>
    <visual name="front_left_through_axle">
      <origin xyz="0.1199 0.1199 0.0550" rpy="0 1.5708 0.7854" />
      <geometry>
        <cylinder radius="0.0080" length="0.0750" />
      </geometry>
      <material name="axle_silver" />
    </visual>
    <visual name="front_left_inner_bearing_socket">
      <origin xyz="0.1177 0.1177 0.0550" rpy="0 1.5708 0.7854" />
      <geometry>
        <cylinder radius="0.0200" length="0.0260" />
      </geometry>
      <material name="axle_silver" />
    </visual>
    <visual name="front_right_inner_axle_bracket">
      <origin xyz="0.0955 -0.0955 0.0810" rpy="0 0 -2.3562" />
      <geometry>
        <box size="0.052 0.034 0.060" />
      </geometry>
      <material name="mount_dark" />
    </visual>
    <visual name="front_right_through_axle">
      <origin xyz="0.1199 -0.1199 0.0550" rpy="0 1.5708 -0.7854" />
      <geometry>
        <cylinder radius="0.0080" length="0.0750" />
      </geometry>
      <material name="axle_silver" />
    </visual>
    <visual name="front_right_inner_bearing_socket">
      <origin xyz="0.1177 -0.1177 0.0550" rpy="0 1.5708 -0.7854" />
      <geometry>
        <cylinder radius="0.0200" length="0.0260" />
      </geometry>
      <material name="axle_silver" />
    </visual>
    <visual name="rear_left_inner_axle_bracket">
      <origin xyz="-0.0955 0.0955 0.0810" rpy="0 0 0.7854" />
      <geometry>
        <box size="0.052 0.034 0.060" />
      </geometry>
      <material name="mount_dark" />
    </visual>
    <visual name="rear_left_through_axle">
      <origin xyz="-0.1199 0.1199 0.0550" rpy="0 1.5708 2.3562" />
      <geometry>
        <cylinder radius="0.0080" length="0.0750" />
      </geometry>
      <material name="axle_silver" />
    </visual>
    <visual name="rear_left_inner_bearing_socket">
      <origin xyz="-0.1177 0.1177 0.0550" rpy="0 1.5708 2.3562" />
      <geometry>
        <cylinder radius="0.0200" length="0.0260" />
      </geometry>
      <material name="axle_silver" />
    </visual>
    <visual name="rear_right_inner_axle_bracket">
      <origin xyz="-0.0955 -0.0955 0.0810" rpy="0 0 -3.9270" />
      <geometry>
        <box size="0.052 0.034 0.060" />
      </geometry>
      <material name="mount_dark" />
    </visual>
    <visual name="rear_right_through_axle">
      <origin xyz="-0.1199 -0.1199 0.0550" rpy="0 1.5708 -2.3562" />
      <geometry>
        <cylinder radius="0.0080" length="0.0750" />
      </geometry>
      <material name="axle_silver" />
    </visual>
    <visual name="rear_right_inner_bearing_socket">
      <origin xyz="-0.1177 -0.1177 0.0550" rpy="0 1.5708 -2.3562" />
      <geometry>
        <cylinder radius="0.0200" length="0.0260" />
      </geometry>
      <material name="axle_silver" />
    </visual>
    <collision name="chassis_collision">
      <origin xyz="0 0 0.1250" rpy="0 0 0" />
      <geometry>
        <cylinder radius="0.2500" length="0.0600" />
      </geometry>
    </collision>
    <visual name="front_direction_marker">
      <origin xyz="0.23 0 0.165" rpy="0 0 0" />
      <geometry>
        <box size="0.04 0.04 0.02" />
      </geometry>
      <material name="orange_marker">
        <color rgba="1.0 0.5 0.0 1.0" />
      </material>
    </visual>
  </link>
  <link name="front_left_omni_wheel_link">
    <inertial>
      <origin xyz="0 0 0" rpy="0 0 0" />
      <mass value="0.25000" />
      <inertia ixx="0.00021500" ixy="0" ixz="0" iyy="0.00031300" iyz="0" izz="0.00021500" />
    </inertial>
    <visual name="front_left_high_resolution_omni_wheel_metal">
      <origin xyz="0 0 0" rpy="0 0 0" />
      <geometry>
        <mesh filename="package://sweeper_robot_omni4_base_ros/meshes/omni_wheel_metal.stl" />
      </geometry>
      <material name="wheel_silver" />
    </visual>
    <visual name="front_left_high_resolution_omni_wheel_rollers">
      <origin xyz="0 0 0" rpy="0 0 0" />
      <geometry>
        <mesh filename="package://sweeper_robot_omni4_base_ros/meshes/omni_wheel_rollers.stl" />
      </geometry>
      <material name="roller_light" />
    </visual>
    <collision name="front_left_wheel_collision">
      <origin xyz="0 0 0" rpy="1.5708 0 0" />
      <geometry>
        <cylinder radius="0.0500" length="0.0530" />
      </geometry>
    </collision>
  </link>
  <joint name="front_left_omni_wheel_joint" type="continuous">
    <parent link="base_link" />
    <child link="front_left_omni_wheel_link" />
    <origin xyz="0.1450 0.1450 0.0550" rpy="0 0 -0.7854" />
    <axis xyz="0 1 0" />
  </joint>
  <link name="front_right_omni_wheel_link">
    <inertial>
      <origin xyz="0 0 0" rpy="0 0 0" />
      <mass value="0.25000" />
      <inertia ixx="0.00021500" ixy="0" ixz="0" iyy="0.00031300" iyz="0" izz="0.00021500" />
    </inertial>
    <visual name="front_right_high_resolution_omni_wheel_metal">
      <origin xyz="0 0 0" rpy="0 0 0" />
      <geometry>
        <mesh filename="package://sweeper_robot_omni4_base_ros/meshes/omni_wheel_metal.stl" />
      </geometry>
      <material name="wheel_silver" />
    </visual>
    <visual name="front_right_high_resolution_omni_wheel_rollers">
      <origin xyz="0 0 0" rpy="0 0 0" />
      <geometry>
        <mesh filename="package://sweeper_robot_omni4_base_ros/meshes/omni_wheel_rollers.stl" />
      </geometry>
      <material name="roller_light" />
    </visual>
    <collision name="front_right_wheel_collision">
      <origin xyz="0 0 0" rpy="1.5708 0 0" />
      <geometry>
        <cylinder radius="0.0500" length="0.0530" />
      </geometry>
    </collision>
  </link>
  <joint name="front_right_omni_wheel_joint" type="continuous">
    <parent link="base_link" />
    <child link="front_right_omni_wheel_link" />
    <origin xyz="0.1450 -0.1450 0.0550" rpy="0 0 -2.3562" />
    <axis xyz="0 1 0" />
  </joint>
  <link name="rear_left_omni_wheel_link">
    <inertial>
      <origin xyz="0 0 0" rpy="0 0 0" />
      <mass value="0.25000" />
      <inertia ixx="0.00021500" ixy="0" ixz="0" iyy="0.00031300" iyz="0" izz="0.00021500" />
    </inertial>
    <visual name="rear_left_high_resolution_omni_wheel_metal">
      <origin xyz="0 0 0" rpy="0 0 0" />
      <geometry>
        <mesh filename="package://sweeper_robot_omni4_base_ros/meshes/omni_wheel_metal.stl" />
      </geometry>
      <material name="wheel_silver" />
    </visual>
    <visual name="rear_left_high_resolution_omni_wheel_rollers">
      <origin xyz="0 0 0" rpy="0 0 0" />
      <geometry>
        <mesh filename="package://sweeper_robot_omni4_base_ros/meshes/omni_wheel_rollers.stl" />
      </geometry>
      <material name="roller_light" />
    </visual>
    <collision name="rear_left_wheel_collision">
      <origin xyz="0 0 0" rpy="1.5708 0 0" />
      <geometry>
        <cylinder radius="0.0500" length="0.0530" />
      </geometry>
    </collision>
  </link>
  <joint name="rear_left_omni_wheel_joint" type="continuous">
    <parent link="base_link" />
    <child link="rear_left_omni_wheel_link" />
    <origin xyz="-0.1450 0.1450 0.0550" rpy="0 0 0.7854" />
    <axis xyz="0 1 0" />
  </joint>
  <link name="rear_right_omni_wheel_link">
    <inertial>
      <origin xyz="0 0 0" rpy="0 0 0" />
      <mass value="0.25000" />
      <inertia ixx="0.00021500" ixy="0" ixz="0" iyy="0.00031300" iyz="0" izz="0.00021500" />
    </inertial>
    <visual name="rear_right_high_resolution_omni_wheel_metal">
      <origin xyz="0 0 0" rpy="0 0 0" />
      <geometry>
        <mesh filename="package://sweeper_robot_omni4_base_ros/meshes/omni_wheel_metal.stl" />
      </geometry>
      <material name="wheel_silver" />
    </visual>
    <visual name="rear_right_high_resolution_omni_wheel_rollers">
      <origin xyz="0 0 0" rpy="0 0 0" />
      <geometry>
        <mesh filename="package://sweeper_robot_omni4_base_ros/meshes/omni_wheel_rollers.stl" />
      </geometry>
      <material name="roller_light" />
    </visual>
    <collision name="rear_right_wheel_collision">
      <origin xyz="0 0 0" rpy="1.5708 0 0" />
      <geometry>
        <cylinder radius="0.0500" length="0.0530" />
      </geometry>
    </collision>
  </link>
  <joint name="rear_right_omni_wheel_joint" type="continuous">
    <parent link="base_link" />
    <child link="rear_right_omni_wheel_link" />
    <origin xyz="-0.1450 -0.1450 0.0550" rpy="0 0 -3.9270" />
    <axis xyz="0 1 0" />
  </joint>
  <link name="lidar_link">
    <inertial>
      <origin xyz="0 0 0.032" rpy="0 0 0" />
      <mass value="0.18000" />
      <inertia ixx="0.00008000" ixy="0" ixz="0" iyy="0.00008000" iyz="0" izz="0.00010000" />
    </inertial>
    <visual name="lidar_blue_body">
      <origin xyz="0 0 0.0275" rpy="0 0 0" />
      <geometry>
        <cylinder radius="0.0400" length="0.0550" />
      </geometry>
      <material name="lidar_blue" />
    </visual>
    <visual name="lidar_dark_cap">
      <origin xyz="0 0 0.0590" rpy="0 0 0" />
      <geometry>
        <cylinder radius="0.0410" length="0.0080" />
      </geometry>
      <material name="sensor_dark" />
    </visual>
    <collision name="lidar_collision">
      <origin xyz="0 0 0.032" rpy="0 0 0" />
      <geometry>
        <cylinder radius="0.0410" length="0.0630" />
      </geometry>
    </collision>
  </link>
  <joint name="lidar_joint" type="fixed">
    <parent link="base_link" />
    <child link="lidar_link" />
    <origin xyz="0.000 0.075 0.1610" rpy="0 0 0" />
  </joint>
  <link name="odometry_link">
    <inertial>
      <origin xyz="0 0 0.023" rpy="0 0 0" />
      <mass value="0.12000" />
      <inertia ixx="0.00006000" ixy="0" ixz="0" iyy="0.00010000" iyz="0" izz="0.00011000" />
    </inertial>
    <visual name="orange_odometry_box">
      <origin xyz="0 0 0.020" rpy="0 0 0" />
      <geometry>
        <box size="0.088 0.062 0.040" />
      </geometry>
      <material name="odometry_orange" />
    </visual>
    <visual name="odometry_top_dark">
      <origin xyz="0 0 0.043" rpy="0 0 0" />
      <geometry>
        <box size="0.088 0.062 0.006" />
      </geometry>
      <material name="sensor_dark" />
    </visual>
    <!-- <collision name="odometry_collision">
      <origin xyz="0 0 0.023" rpy="0 0 0" />
      <geometry>
        <box size="0.088 0.062 0.046" />
      </geometry>
    </collision> -->
  </link>
  <joint name="odometry_joint" type="fixed">
    <parent link="base_link" />
    <child link="odometry_link" />
    <origin xyz="0.085 -0.060 0.1610" rpy="0 0 0" />
  </joint>
  <link name="cmd_vel_interface_link">
    <inertial>
      <origin xyz="0 0 0.025" rpy="0 0 0" />
      <mass value="0.08000" />
      <inertia ixx="0.00005000" ixy="0" ixz="0" iyy="0.00006000" iyz="0" izz="0.00008000" />
    </inertial>
    <visual name="green_speed_control_interface_board">
      <origin xyz="0 0 0.004" rpy="0 0 0" />
      <geometry>
        <box size="0.090 0.060 0.008" />
      </geometry>
      <material name="interface_green" />
    </visual>
    <visual name="upright_cmd_vel_socket_panel">
      <origin xyz="0 0.025 0.037" rpy="0 0 0" />
      <geometry>
        <box size="0.072 0.008 0.058" />
      </geometry>
      <material name="interface_green" />
    </visual>
    <visual name="dark_command_socket">
      <origin xyz="0.000 0.020 0.040" rpy="0 0 0" />
      <geometry>
        <box size="0.046 0.010 0.022" />
      </geometry>
      <material name="sensor_dark" />
    </visual>
    <visual name="cmd_vel_pin_left">
      <origin xyz="-0.020 0.014 0.021" rpy="1.5708 0 0" />
      <geometry>
        <cylinder radius="0.0035" length="0.016" />
      </geometry>
      <material name="interface_gold" />
    </visual>
    <visual name="cmd_vel_pin_right">
      <origin xyz="0.020 0.014 0.021" rpy="1.5708 0 0" />
      <geometry>
        <cylinder radius="0.0035" length="0.016" />
      </geometry>
      <material name="interface_gold" />
    </visual>
    <!-- <collision name="cmd_vel_interface_collision">
      <origin xyz="0 0 0.025" rpy="0 0 0" />
      <geometry>
        <box size="0.100 0.080 0.066" />
      </geometry>
    </collision> -->
  </link>
  <joint name="cmd_vel_interface_joint" type="fixed">
    <parent link="base_link" />
    <child link="cmd_vel_interface_link" />
    <origin xyz="-0.085 -0.060 0.1590" rpy="0 0 0" />
  </joint>
  <gazebo>
    <plugin name="omni_drive_controller" filename="libgazebo_ros_planar_move.so">
      <robotNamespace>/</robotNamespace>
      <commandTopic>cmd_vel</commandTopic>
      <odometryTopic>odom</odometryTopic>
      <odometryFrame>odom</odometryFrame>
      <robotBaseFrame>base_footprint</robotBaseFrame>
      <publishOdomTF>true</publishOdomTF>
      <publishWheelTF>false</publishWheelTF>
      <odometryRate>50.0</odometryRate>
      <updateRate>50.0</updateRate>
      <!-- Stop the base if /cmd_vel is not refreshed within this interval. -->
      <cmdTimeout>0.2</cmdTimeout>
    </plugin>
  </gazebo>
  <gazebo reference="lidar_link">
    <sensor type="ray" name="lidar_2d_sensor">
      <pose>0 0 0.035 0 0 0</pose>
      <visualize>true</visualize>
      <update_rate>10</update_rate>
      <ray>
        <scan>
          <horizontal>
            <samples>720</samples>
            <resolution>1</resolution>
            <min_angle>-3.1415926</min_angle>
            <max_angle>3.1415926</max_angle>
          </horizontal>
        </scan>
        <range>
          <min>0.08</min>
          <max>8.0</max>
          <resolution>0.01</resolution>
        </range>
        <noise>
          <type>gaussian</type>
          <mean>0.0</mean>
          <stddev>0.01</stddev>
        </noise>
      </ray>
      <plugin name="gazebo_ros_laser_controller" filename="libgazebo_ros_laser.so">
        <topicName>/scan</topicName>
        <frameName>lidar_link</frameName>
      </plugin>
    </sensor>
  </gazebo>
  <gazebo reference="base_link">
    <material>Gazebo/DarkGrey</material>
  </gazebo>
  <gazebo reference="lidar_link">
    <material>Gazebo/Blue</material>
  </gazebo>
  <gazebo reference="odometry_link">
    <material>Gazebo/Orange</material>
  </gazebo>
  <gazebo reference="cmd_vel_interface_link">
    <material>Gazebo/Green</material>
  </gazebo>
  <gazebo reference="front_left_omni_wheel_link">
    <mu1>0.8</mu1>
    <mu2>0.8</mu2>
    <kp>100000.0</kp>
    <kd>1.0</kd>
  </gazebo>
  <gazebo reference="front_right_omni_wheel_link">
    <mu1>0.8</mu1>
    <mu2>0.8</mu2>
    <kp>100000.0</kp>
    <kd>1.0</kd>
  </gazebo>
  <gazebo reference="rear_left_omni_wheel_link">
    <mu1>0.8</mu1>
    <mu2>0.8</mu2>
    <kp>100000.0</kp>
    <kd>1.0</kd>
  </gazebo>
  <gazebo reference="rear_right_omni_wheel_link">
    <mu1>0.8</mu1>
    <mu2>0.8</mu2>
    <kp>100000.0</kp>
    <kd>1.0</kd>
  </gazebo>
</robot>
